<sdf version='1.6'>
  <world name='default'>
    <light name='sun' type='directional'>
      <cast_shadows>1</cast_shadows>
      <pose frame=''>0 0 10 0 -0 0</pose>
      <diffuse>0.8 0.8 0.8 1</diffuse>
      <specular>0.1 0.1 0.1 1</specular>
      <attenuation>
        <range>1000</range>
        <constant>0.9</constant>
        <linear>0.01</linear>
        <quadratic>0.001</quadratic>
      </attenuation>
      <direction>-0.5 0.5 -1</direction>
    </light>
    <model name='ground_plane'>
      <static>1</static>
      <link name='link'>
        <collision name='collision'>
          <geometry>
            <plane>
              <normal>0 0 1</normal>
              <size>100 100</size>
            </plane>
          </geometry>
          <surface>
            <friction>
              <ode>
                <mu>100</mu>
                <mu2>50</mu2>
              </ode>
              <torsional>
                <ode/>
              </torsional>
            </friction>
            <contact>
              <ode/>
            </contact>
            <bounce/>
          </surface>
          <max_contacts>10</max_contacts>
        </collision>
        <visual name='visual'>
          <cast_shadows>0</cast_shadows>
          <geometry>
            <plane>
              <normal>0 0 1</normal>
              <size>100 100</size>
            </plane>
          </geometry>
          <material>
            <script>
              <uri>file://media/materials/scripts/gazebo.material</uri>
              <name>Gazebo/Grey</name>
            </script>
          </material>
        </visual>
        <self_collide>0</self_collide>
        <kinematic>0</kinematic>
        <gravity>1</gravity>
      </link>
    </model>
    <gravity>0 0 -9.8</gravity>
    <magnetic_field>6e-06 2.3e-05 -4.2e-05</magnetic_field>
    <atmosphere type='adiabatic'/>
    <physics name='default_physics' default='0' type='ode'>
      <max_step_size>0.001</max_step_size>
      <real_time_factor>1</real_time_factor>
      <real_time_update_rate>1000</real_time_update_rate>
    </physics>
    <scene>
      <ambient>0.4 0.4 0.4 1</ambient>
      <background>0.7 0.7 0.7 1</background>
      <shadows>1</shadows>
    </scene>
    <spherical_coordinates>
      <surface_model>EARTH_WGS84</surface_model>
      <latitude_deg>0</latitude_deg>
      <longitude_deg>0</longitude_deg>
      <elevation>0</elevation>
      <heading_deg>0</heading_deg>
    </spherical_coordinates>
    <model name='Untitled'>
      <pose frame=''>1.50483 -0.146788 0 0 -0 0</pose>
      <link name='Wall_0'>
        <collision name='Wall_0_Collision'>
          <geometry>
            <box>
              <size>14.5 0.15 2.5</size>
            </box>
          </geometry>
          <pose frame=''>0 0 1.25 0 -0 0</pose>
          <max_contacts>10</max_contacts>
          <surface>
            <contact>
              <ode/>
            </contact>
            <bounce/>
            <friction>
              <torsional>
                <ode/>
              </torsional>
              <ode/>
            </friction>
          </surface>
        </collision>
        <visual name='Wall_0_Visual'>
          <pose frame=''>0 0 1.25 0 -0 0</pose>
          <geometry>
            <box>
              <size>14.5 0.15 2.5</size>
            </box>
          </geometry>
          <material>
            <script>
              <uri>file://media/materials/scripts/gazebo.material</uri>
              <name>Gazebo/Bricks</name>
            </script>
            <ambient>1 1 1 1</ambient>
          </material>
        </visual>
        <pose frame=''>10.3 -1.75 0 0 -0 1.5708</pose>
        <self_collide>0</self_collide>
        <kinematic>0</kinematic>
        <gravity>1</gravity>
      </link>
      <link name='Wall_1'>
        <collision name='Wall_1_Collision'>
          <geometry>
            <box>
              <size>3.25 0.15 2.5</size>
            </box>
          </geometry>
          <pose frame=''>0 0 1.25 0 -0 0</pose>
          <max_contacts>10</max_contacts>
          <surface>
            <contact>
              <ode/>
            </contact>
            <bounce/>
            <friction>
              <torsional>
                <ode/>
              </torsional>
              <ode/>
            </friction>
          </surface>
        </collision>
        <visual name='Wall_1_Visual'>
          <pose frame=''>0 0 1.25 0 -0 0</pose>
          <geometry>
            <box>
              <size>3.25 0.15 2.5</size>
            </box>
          </geometry>
          <material>
            <script>
              <uri>file://media/materials/scripts/gazebo.material</uri>
              <name>Gazebo/Bricks</name>
            </script>
            <ambient>1 1 1 1</ambient>
          </material>
        </visual>
        <pose frame=''>10.3 6.975 0 0 -0 1.5708</pose>
        <self_collide>0</self_collide>
        <kinematic>0</kinematic>
        <gravity>1</gravity>
      </link>
      <link name='Wall_3'>
        <collision name='Wall_3_Collision'>
          <geometry>
            <box>
              <size>20.75 0.15 2.5</size>
            </box>
          </geometry>
          <pose frame=''>0 0 1.25 0 -0 0</pose>
          <max_contacts>10</max_contacts>
          <surface>
            <contact>
              <ode/>
            </contact>
            <bounce/>
            <friction>
              <torsional>
                <ode/>
              </torsional>
              <ode/>
            </friction>
          </surface>
        </collision>
        <visual name='Wall_3_Visual'>
          <pose frame=''>0 0 1.25 0 -0 0</pose>
          <geometry>
            <box>
              <size>20.75 0.15 2.5</size>
            </box>
          </geometry>
          <material>
            <script>
              <uri>file://media/materials/scripts/gazebo.material</uri>
              <name>Gazebo/Bricks</name>
            </script>
            <ambient>1 1 1 1</ambient>
          </material>
        </visual>
        <pose frame=''>0 -8.925 0 0 -0 3.14159</pose>
        <self_collide>0</self_collide>
        <kinematic>0</kinematic>
        <gravity>1</gravity>
      </link>
      <link name='Wall_4'>
        <collision name='Wall_4_Collision'>
          <geometry>
            <box>
              <size>18 0.15 2.5</size>
            </box>
          </geometry>
          <pose frame=''>0 0 1.25 0 -0 0</pose>
          <max_contacts>10</max_contacts>
          <surface>
            <contact>
              <ode/>
            </contact>
            <bounce/>
            <friction>
              <torsional>
                <ode/>
              </torsional>
              <ode/>
            </friction>
          </surface>
        </collision>
        <visual name='Wall_4_Visual'>
          <pose frame=''>0 0 1.25 0 -0 0</pose>
          <geometry>
            <box>
              <size>18 0.15 2.5</size>
            </box>
          </geometry>
          <material>
            <script>
              <uri>file://media/materials/scripts/gazebo.material</uri>
              <name>Gazebo/Bricks</name>
            </script>
            <ambient>1 1 1 1</ambient>
          </material>
        </visual>
        <pose frame=''>-10.3 0 0 0 -0 1.5708</pose>
        <self_collide>0</self_collide>
        <kinematic>0</kinematic>
        <gravity>1</gravity>
      </link>
      <link name='Wall_5'>
        <collision name='Wall_5_Collision'>
          <geometry>
            <box>
              <size>20.75 0.15 2.5</size>
            </box>
          </geometry>
          <pose frame=''>0 0 1.25 0 -0 0</pose>
          <max_contacts>10</max_contacts>
          <surface>
            <contact>
              <ode/>
            </contact>
            <bounce/>
            <friction>
              <torsional>
                <ode/>
              </torsional>
              <ode/>
            </friction>
          </surface>
        </collision>
        <visual name='Wall_5_Visual'>
          <pose frame=''>0 0 1.25 0 -0 0</pose>
          <geometry>
            <box>
              <size>20.75 0.15 2.5</size>
            </box>
          </geometry>
          <material>
            <script>
              <uri>file://media/materials/scripts/gazebo.material</uri>
              <name>Gazebo/Bricks</name>
            </script>
            <ambient>1 1 1 1</ambient>
          </material>
        </visual>
        <pose frame=''>0 8.925 0 0 -0 0</pose>
        <self_collide>0</self_collide>
        <kinematic>0</kinematic>
        <gravity>1</gravity>
      </link>
      <link name='Wall_6'>
        <collision name='Wall_6_Collision'>
          <geometry>
            <box>
              <size>1.25 0.15 2.5</size>
            </box>
          </geometry>
          <pose frame=''>0 0 1.25 0 -0 0</pose>
          <max_contacts>10</max_contacts>
          <surface>
            <contact>
              <ode/>
            </contact>
            <bounce/>
            <friction>
              <torsional>
                <ode/>
              </torsional>
              <ode/>
            </friction>
          </surface>
        </collision>
        <visual name='Wall_6_Visual'>
          <pose frame=''>0 0 1.25 0 -0 0</pose>
          <geometry>
            <box>
              <size>1.25 0.15 2.5</size>
            </box>
          </geometry>
          <material>
            <script>
              <uri>file://media/materials/scripts/gazebo.material</uri>
              <name>Gazebo/Bricks</name>
            </script>
            <ambient>1 1 1 1</ambient>
          </material>
        </visual>
        <pose frame=''>10.3 8.375 0 0 0 -1.5708</pose>
        <self_collide>0</self_collide>
        <kinematic>0</kinematic>
        <gravity>1</gravity>
      </link>
      <static>1</static>
    </model>
    <model name='unit_box_0'>
      <pose frame=''>-6.96472 -6.96388 0.5 0 -0 0</pose>
      <link name='link'>
        <inertial>
          <mass>1</mass>
          <inertia>
            <ixx>0.166667</ixx>
            <ixy>0</ixy>
            <ixz>0</ixz>
            <iyy>0.166667</iyy>
            <iyz>0</iyz>
            <izz>0.166667</izz>
          </inertia>
        </inertial>
        <collision name='collision'>
          <geometry>
            <box>
              <size>1 1 1</size>
            </box>
          </geometry>
          <max_contacts>10</max_contacts>
          <surface>
            <contact>
              <ode/>
            </contact>
            <bounce/>
            <friction>
              <torsional>
                <ode/>
              </torsional>
              <ode/>
            </friction>
          </surface>
        </collision>
        <visual name='visual'>
          <geometry>
            <box>
              <size>1 1 1</size>
            </box>
          </geometry>
          <material>
            <script>
              <name>Gazebo/Grey</name>
              <uri>file://media/materials/scripts/gazebo.material</uri>
            </script>
          </material>
        </visual>
        <self_collide>0</self_collide>
        <kinematic>0</kinematic>
        <gravity>1</gravity>
      </link>
    </model>
    <model name='unit_box_1'>
      <pose frame=''>-7.07039 7.24523 0.5 0 -0 0</pose>
      <link name='link'>
        <inertial>
          <mass>1</mass>
          <inertia>
            <ixx>0.166667</ixx>
            <ixy>0</ixy>
            <ixz>0</ixz>
            <iyy>0.166667</iyy>
            <iyz>0</iyz>
            <izz>0.166667</izz>
          </inertia>
        </inertial>
        <collision name='collision'>
          <geometry>
            <box>
              <size>1 1 1</size>
            </box>
          </geometry>
          <max_contacts>10</max_contacts>
          <surface>
            <contact>
              <ode/>
            </contact>
            <bounce/>
            <friction>
              <torsional>
                <ode/>
              </torsional>
              <ode/>
            </friction>
          </surface>
        </collision>
        <visual name='visual'>
          <geometry>
            <box>
              <size>1 1 1</size>
            </box>
          </geometry>
          <material>
            <script>
              <name>Gazebo/Grey</name>
              <uri>file://media/materials/scripts/gazebo.material</uri>
            </script>
          </material>
        </visual>
        <self_collide>0</self_collide>
        <kinematic>0</kinematic>
        <gravity>1</gravity>
      </link>
    </model>
    <model name='unit_cylinder_0'>
      <pose frame=''>-2.96281 7.34822 0.5 0 -0 0</pose>
      <link name='link'>
        <inertial>
          <mass>1</mass>
          <inertia>
            <ixx>0.145833</ixx>
            <ixy>0</ixy>
            <ixz>0</ixz>
            <iyy>0.145833</iyy>
            <iyz>0</iyz>
            <izz>0.125</izz>
          </inertia>
        </inertial>
        <collision name='collision'>
          <geometry>
            <cylinder>
              <radius>0.5</radius>
              <length>1</length>
            </cylinder>
          </geometry>
          <max_contacts>10</max_contacts>
          <surface>
            <contact>
              <ode/>
            </contact>
            <bounce/>
            <friction>
              <torsional>
                <ode/>
              </torsional>
              <ode/>
            </friction>
          </surface>
        </collision>
        <visual name='visual'>
          <geometry>
            <cylinder>
              <radius>0.5</radius>
              <length>1</length>
            </cylinder>
          </geometry>
          <material>
            <script>
              <name>Gazebo/Grey</name>
              <uri>file://media/materials/scripts/gazebo.material</uri>
            </script>
          </material>
        </visual>
        <self_collide>0</self_collide>
        <kinematic>0</kinematic>
        <gravity>1</gravity>
      </link>
    </model>
    <model name='unit_cylinder_1'>
      <pose frame=''>0.419896 7.25053 0.5 0 -0 0</pose>
      <link name='link'>
        <inertial>
          <mass>1</mass>
          <inertia>
            <ixx>0.145833</ixx>
            <ixy>0</ixy>
            <ixz>0</ixz>
            <iyy>0.145833</iyy>
            <iyz>0</iyz>
            <izz>0.125</izz>
          </inertia>
        </inertial>
        <collision name='collision'>
          <geometry>
            <cylinder>
              <radius>0.5</radius>
              <length>1</length>
            </cylinder>
          </geometry>
          <max_contacts>10</max_contacts>
          <surface>
            <contact>
              <ode/>
            </contact>
            <bounce/>
            <friction>
              <torsional>
                <ode/>
              </torsional>
              <ode/>
            </friction>
          </surface>
        </collision>
        <visual name='visual'>
          <geometry>
            <cylinder>
              <radius>0.5</radius>
              <length>1</length>
            </cylinder>
          </geometry>
          <material>
            <script>
              <name>Gazebo/Grey</name>
              <uri>file://media/materials/scripts/gazebo.material</uri>
            </script>
          </material>
        </visual>
        <self_collide>0</self_collide>
        <kinematic>0</kinematic>
        <gravity>1</gravity>
      </link>
    </model>
    <model name='unit_cylinder_2'>
      <pose frame=''>3.58677 7.36506 0.5 0 -0 0</pose>
      <link name='link'>
        <inertial>
          <mass>1</mass>
          <inertia>
            <ixx>0.145833</ixx>
            <ixy>0</ixy>
            <ixz>0</ixz>
            <iyy>0.145833</iyy>
            <iyz>0</iyz>
            <izz>0.125</izz>
          </inertia>
        </inertial>
        <collision name='collision'>
          <geometry>
            <cylinder>
              <radius>0.5</radius>
              <length>1</length>
            </cylinder>
          </geometry>
          <max_contacts>10</max_contacts>
          <surface>
            <contact>
              <ode/>
            </contact>
            <bounce/>
            <friction>
              <torsional>
                <ode/>
              </torsional>
              <ode/>
            </friction>
          </surface>
        </collision>
        <visual name='visual'>
          <geometry>
            <cylinder>
              <radius>0.5</radius>
              <length>1</length>
            </cylinder>
          </geometry>
          <material>
            <script>
              <name>Gazebo/Grey</name>
              <uri>file://media/materials/scripts/gazebo.material</uri>
            </script>
          </material>
        </visual>
        <self_collide>0</self_collide>
        <kinematic>0</kinematic>
        <gravity>1</gravity>
      </link>
    </model>
    <model name='unit_sphere_0'>
      <pose frame=''>6.37672 7.04879 0.5 0 -0 0</pose>
      <link name='link'>
        <inertial>
          <mass>1</mass>
          <inertia>
            <ixx>0.1</ixx>
            <ixy>0</ixy>
            <ixz>0</ixz>
            <iyy>0.1</iyy>
            <iyz>0</iyz>
            <izz>0.1</izz>
          </inertia>
        </inertial>
        <collision name='collision'>
          <geometry>
            <sphere>
              <radius>0.5</radius>
            </sphere>
          </geometry>
          <max_contacts>10</max_contacts>
          <surface>
            <contact>
              <ode/>
            </contact>
            <bounce/>
            <friction>
              <torsional>
                <ode/>
              </torsional>
              <ode/>
            </friction>
          </surface>
        </collision>
        <visual name='visual'>
          <geometry>
            <sphere>
              <radius>0.5</radius>
            </sphere>
          </geometry>
          <material>
            <script>
              <name>Gazebo/Grey</name>
              <uri>file://media/materials/scripts/gazebo.material</uri>
            </script>
          </material>
        </visual>
        <self_collide>0</self_collide>
        <kinematic>0</kinematic>
        <gravity>1</gravity>
      </link>
    </model>
    <model name='cube_20k'>
      <link name='link'>
        <pose frame=''>0 0 0.5 0 -0 0</pose>
        <collision name='collision'>
          <geometry>
            <mesh>
              <uri>model://cube_20k/meshes/cube_20k.stl</uri>
              <scale>1 1 1</scale>
            </mesh>
          </geometry>
          <max_contacts>10</max_contacts>
          <surface>
            <contact>
              <ode/>
            </contact>
            <bounce/>
            <friction>
              <torsional>
                <ode/>
              </torsional>
              <ode/>
            </friction>
          </surface>
        </collision>
        <visual name='visual'>
          <geometry>
            <mesh>
              <uri>model://cube_20k/meshes/cube_20k.stl</uri>
              <scale>1 1 1</scale>
            </mesh>
          </geometry>
        </visual>
        <self_collide>0</self_collide>
        <inertial>
          <inertia>
            <ixx>1</ixx>
            <ixy>0</ixy>
            <ixz>0</ixz>
            <iyy>1</iyy>
            <iyz>0</iyz>
            <izz>1</izz>
          </inertia>
          <mass>1</mass>
        </inertial>
        <kinematic>0</kinematic>
        <gravity>1</gravity>
      </link>
      <pose frame=''>-3.73378 -7.06091 0 0 -0 0</pose>
    </model>
    <model name='cube_20k_0'>
      <link name='link'>
        <pose frame=''>0 0 0.5 0 -0 0</pose>
        <collision name='collision'>
          <geometry>
            <mesh>
              <uri>model://cube_20k/meshes/cube_20k.stl</uri>
              <scale>1 1 1</scale>
            </mesh>
          </geometry>
          <max_contacts>10</max_contacts>
          <surface>
            <contact>
              <ode/>
            </contact>
            <bounce/>
            <friction>
              <torsional>
                <ode/>
              </torsional>
              <ode/>
            </friction>
          </surface>
        </collision>
        <visual name='visual'>
          <geometry>
            <mesh>
              <uri>model://cube_20k/meshes/cube_20k.stl</uri>
              <scale>1 1 1</scale>
            </mesh>
          </geometry>
        </visual>
        <self_collide>0</self_collide>
        <inertial>
          <inertia>
            <ixx>1</ixx>
            <ixy>0</ixy>
            <ixz>0</ixz>
            <iyy>1</iyy>
            <iyz>0</iyz>
            <izz>1</izz>
          </inertia>
          <mass>1</mass>
        </inertial>
        <kinematic>0</kinematic>
        <gravity>1</gravity>
      </link>
      <pose frame=''>-0.283554 -6.91074 0 0 -0 0</pose>
    </model>
    <model name='cube_20k_1'>
      <link name='link'>
        <pose frame=''>0 0 0.5 0 -0 0</pose>
        <collision name='collision'>
          <geometry>
            <mesh>
              <uri>model://cube_20k/meshes/cube_20k.stl</uri>
              <scale>1 1 1</scale>
            </mesh>
          </geometry>
          <max_contacts>10</max_contacts>
          <surface>
            <contact>
              <ode/>
            </contact>
            <bounce/>
            <friction>
              <torsional>
                <ode/>
              </torsional>
              <ode/>
            </friction>
          </surface>
        </collision>
        <visual name='visual'>
          <geometry>
            <mesh>
              <uri>model://cube_20k/meshes/cube_20k.stl</uri>
              <scale>1 1 1</scale>
            </mesh>
          </geometry>
        </visual>
        <self_collide>0</self_collide>
        <inertial>
          <inertia>
            <ixx>1</ixx>
            <ixy>0</ixy>
            <ixz>0</ixz>
            <iyy>1</iyy>
            <iyz>0</iyz>
            <izz>1</izz>
          </inertia>
          <mass>1</mass>
        </inertial>
        <kinematic>0</kinematic>
        <gravity>1</gravity>
      </link>
      <pose frame=''>3.34153 -6.96407 0 0 -0 0</pose>
    </model>
    <model name='cube_20k_2'>
      <link name='link'>
        <pose frame=''>0 0 0.5 0 -0 0</pose>
        <collision name='collision'>
          <geometry>
            <mesh>
              <uri>model://cube_20k/meshes/cube_20k.stl</uri>
              <scale>1 1 1</scale>
            </mesh>
          </geometry>
          <max_contacts>10</max_contacts>
          <surface>
            <contact>
              <ode/>
            </contact>
            <bounce/>
            <friction>
              <torsional>
                <ode/>
              </torsional>
              <ode/>
            </friction>
          </surface>
        </collision>
        <visual name='visual'>
          <geometry>
            <mesh>
              <uri>model://cube_20k/meshes/cube_20k.stl</uri>
              <scale>1 1 1</scale>
            </mesh>
          </geometry>
        </visual>
        <self_collide>0</self_collide>
        <inertial>
          <inertia>
            <ixx>1</ixx>
            <ixy>0</ixy>
            <ixz>0</ixz>
            <iyy>1</iyy>
            <iyz>0</iyz>
            <izz>1</izz>
          </inertia>
          <mass>1</mass>
        </inertial>
        <kinematic>0</kinematic>
        <gravity>1</gravity>
      </link>
      <pose frame=''>6.77413 -6.96441 0 0 -0 0</pose>
    </model>
    <model name='cafe_table'>
      <static>1</static>
      <link name='link'>
        <collision name='surface'>
          <pose frame=''>0 0 0.755 0 -0 0</pose>
          <geometry>
            <box>
              <size>0.913 0.913 0.04</size>
            </box>
          </geometry>
          <max_contacts>10</max_contacts>
          <surface>
            <contact>
              <ode/>
            </contact>
            <bounce/>
            <friction>
              <torsional>
                <ode/>
              </torsional>
              <ode/>
            </friction>
          </surface>
        </collision>
        <collision name='column'>
          <pose frame=''>0 0 0.37 0 -0 0</pose>
          <geometry>
            <box>
              <size>0.042 0.042 0.74</size>
            </box>
          </geometry>
          <max_contacts>10</max_contacts>
          <surface>
            <contact>
              <ode/>
            </contact>
            <bounce/>
            <friction>
              <torsional>
                <ode/>
              </torsional>
              <ode/>
            </friction>
          </surface>
        </collision>
        <collision name='base'>
          <pose frame=''>0 0 0.02 0 -0 0</pose>
          <geometry>
            <box>
              <size>0.56 0.56 0.04</size>
            </box>
          </geometry>
          <max_contacts>10</max_contacts>
          <surface>
            <contact>
              <ode/>
            </contact>
            <bounce/>
            <friction>
              <torsional>
                <ode/>
              </torsional>
              <ode/>
            </friction>
          </surface>
        </collision>
        <visual name='visual'>
          <geometry>
            <mesh>
              <uri>model://cafe_table/meshes/cafe_table.dae</uri>
              <scale>1 1 1</scale>
            </mesh>
          </geometry>
        </visual>
        <self_collide>0</self_collide>
        <kinematic>0</kinematic>
        <gravity>1</gravity>
      </link>
      <pose frame=''>9.22152 -5.31249 0 0 -0 0</pose>
    </model>
    <model name='pioneer2dx'>
      <link name='chassis'>
        <pose frame=''>0 0 0.16 0 -0 0</pose>
        <inertial>
          <mass>5</mass>
          <inertia>
            <ixx>1</ixx>
            <ixy>0</ixy>
            <ixz>0</ixz>
            <iyy>1</iyy>
            <iyz>0</iyz>
            <izz>1</izz>
          </inertia>
        </inertial>
        <collision name='collision'>
          <geometry>
            <box>
              <size>0.445 0.277 0.17</size>
            </box>
          </geometry>
          <max_contacts>10</max_contacts>
          <surface>
            <contact>
              <ode/>
            </contact>
            <bounce/>
            <friction>
              <torsional>
                <ode/>
              </torsional>
              <ode/>
            </friction>
          </surface>
        </collision>
        <collision name='castor_collision'>
          <pose frame=''>-0.2 0 -0.12 0 -0 0</pose>
          <geometry>
            <sphere>
              <radius>0.04</radius>
            </sphere>
          </geometry>
          <surface>
            <friction>
              <ode>
                <mu>0</mu>
                <mu2>0</mu2>
                <slip1>1</slip1>
                <slip2>1</slip2>
              </ode>
              <torsional>
                <ode/>
              </torsional>
            </friction>
            <contact>
              <ode/>
            </contact>
            <bounce/>
          </surface>
          <max_contacts>10</max_contacts>
        </collision>
        <visual name='visual'>
          <pose frame=''>0 0 0.04 0 -0 0</pose>
          <geometry>
            <mesh>
              <uri>model://pioneer2dx/meshes/chassis.dae</uri>
              <scale>1 1 1</scale>
            </mesh>
          </geometry>
        </visual>
        <visual name='castor_visual'>
          <pose frame=''>-0.2 0 -0.12 0 -0 0</pose>
          <geometry>
            <sphere>
              <radius>0.04</radius>
            </sphere>
          </geometry>
          <material>
            <script>
              <uri>file://media/materials/scripts/gazebo.material</uri>
              <name>Gazebo/FlatBlack</name>
            </script>
          </material>
        </visual>
        <self_collide>0</self_collide>
        <kinematic>0</kinematic>
        <gravity>1</gravity>
      </link>
      <link name='right_wheel'>
        <pose frame=''>0.1 -0.17 0.11 -0 1.5707 1.5707</pose>
        <inertial>
          <mass>0.1</mass>
          <inertia>
            <ixx>1</ixx>
            <ixy>0</ixy>
            <ixz>0</ixz>
            <iyy>1</iyy>
            <iyz>0</iyz>
            <izz>1</izz>
          </inertia>
        </inertial>
        <collision name='collision'>
          <geometry>
            <cylinder>
              <radius>0.11</radius>
              <length>0.05</length>
            </cylinder>
          </geometry>
          <surface>
            <friction>
              <ode>
                <mu>100000</mu>
                <mu2>100000</mu2>
                <slip1>0</slip1>
                <slip2>0</slip2>
              </ode>
              <torsional>
                <ode/>
              </torsional>
            </friction>
            <contact>
              <ode/>
            </contact>
            <bounce/>
          </surface>
          <max_contacts>10</max_contacts>
        </collision>
        <visual name='visual'>
          <geometry>
            <cylinder>
              <radius>0.11</radius>
              <length>0.05</length>
            </cylinder>
          </geometry>
          <material>
            <script>
              <uri>file://media/materials/scripts/gazebo.material</uri>
              <name>Gazebo/FlatBlack</name>
            </script>
          </material>
        </visual>
        <self_collide>0</self_collide>
        <kinematic>0</kinematic>
        <gravity>1</gravity>
      </link>
      <link name='left_wheel'>
        <pose frame=''>0.1 0.17 0.11 -0 1.5707 1.5707</pose>
        <inertial>
          <mass>0.5</mass>
          <inertia>
            <ixx>1</ixx>
            <ixy>0</ixy>
            <ixz>0</ixz>
            <iyy>1</iyy>
            <iyz>0</iyz>
            <izz>1</izz>
          </inertia>
        </inertial>
        <collision name='collision'>
          <geometry>
            <cylinder>
              <radius>0.11</radius>
              <length>0.05</length>
            </cylinder>
          </geometry>
          <surface>
            <friction>
              <ode>
                <mu>100000</mu>
                <mu2>100000</mu2>
                <slip1>0</slip1>
                <slip2>0</slip2>
              </ode>
              <torsional>
                <ode/>
              </torsional>
            </friction>
            <contact>
              <ode/>
            </contact>
            <bounce/>
          </surface>
          <max_contacts>10</max_contacts>
        </collision>
        <visual name='visual'>
          <geometry>
            <cylinder>
              <radius>0.11</radius>
              <length>0.05</length>
            </cylinder>
          </geometry>
          <material>
            <script>
              <uri>file://media/materials/scripts/gazebo.material</uri>
              <name>Gazebo/FlatBlack</name>
            </script>
          </material>
        </visual>
        <self_collide>0</self_collide>
        <kinematic>0</kinematic>
        <gravity>1</gravity>
      </link>
      <joint name='left_wheel_hinge' type='revolute'>
        <pose frame=''>0 0 -0.03 0 -0 0</pose>
        <child>left_wheel</child>
        <parent>chassis</parent>
        <axis>
          <xyz>0 1 0</xyz>
          <use_parent_model_frame>1</use_parent_model_frame>
          <limit>
            <lower>-1e+16</lower>
            <upper>1e+16</upper>
          </limit>
          <dynamics>
            <spring_reference>0</spring_reference>
            <spring_stiffness>0</spring_stiffness>
          </dynamics>
        </axis>
      </joint>
      <joint name='right_wheel_hinge' type='revolute'>
        <pose frame=''>0 0 0.03 0 -0 0</pose>
        <child>right_wheel</child>
        <parent>chassis</parent>
        <axis>
          <xyz>0 1 0</xyz>
          <use_parent_model_frame>1</use_parent_model_frame>
          <limit>
            <lower>-1e+16</lower>
            <upper>1e+16</upper>
          </limit>
          <dynamics>
            <spring_reference>0</spring_reference>
            <spring_stiffness>0</spring_stiffness>
          </dynamics>
        </axis>
      </joint>
      <plugin name='diff_drive' filename='libDiffDrivePlugin.so'>
        <left_joint>left_wheel_hinge</left_joint>
        <right_joint>right_wheel_hinge</right_joint>
        <torque>5</torque>
      </plugin>
      <pose frame=''>-5.00969 -4.61947 0 0 -0 0</pose>
    </model>
    <model name='pioneer3at'>
      <pose frame=''>-2.4078 -4.37174 0.18 0 -0 0</pose>
      <static>0</static>
      <link name='chassis'>
        <inertial>
          <mass>14</mass>
          <inertia>
            <ixx>0.3338</ixx>
            <ixy>0</ixy>
            <ixz>0</ixz>
            <iyy>0.4783</iyy>
            <iyz>0</iyz>
            <izz>0.3338</izz>
          </inertia>
        </inertial>
        <collision name='collision'>
          <geometry>
            <box>
              <size>0.501 0.4 0.19</size>
            </box>
          </geometry>
          <max_contacts>10</max_contacts>
          <surface>
            <contact>
              <ode/>
            </contact>
            <bounce/>
            <friction>
              <torsional>
                <ode/>
              </torsional>
              <ode/>
            </friction>
          </surface>
        </collision>
        <visual name='visual'>
          <geometry>
            <mesh>
              <uri>model://pioneer3at/meshes/chassis.dae</uri>
              <scale>1 1 1</scale>
            </mesh>
          </geometry>
        </visual>
        <self_collide>0</self_collide>
        <kinematic>0</kinematic>
        <gravity>1</gravity>
      </link>
      <link name='right_front_wheel'>
        <pose frame=''>0.125 -0.201 -0.06 1.5707 -0 0</pose>
        <collision name='collision'>
          <geometry>
            <cylinder>
              <radius>0.11</radius>
              <length>0.075</length>
            </cylinder>
          </geometry>
          <surface>
            <friction>
              <ode>
                <mu>1</mu>
                <mu2>1</mu2>
                <slip1>0.5</slip1>
                <slip2>0</slip2>
              </ode>
              <torsional>
                <ode/>
              </torsional>
            </friction>
            <contact>
              <ode/>
            </contact>
            <bounce/>
          </surface>
          <max_contacts>10</max_contacts>
        </collision>
        <visual name='visual'>
          <geometry>
            <mesh>
              <uri>model://pioneer3at/meshes/wheel.dae</uri>
              <scale>1 1 1</scale>
            </mesh>
          </geometry>
        </visual>
        <self_collide>0</self_collide>
        <inertial>
          <inertia>
            <ixx>1</ixx>
            <ixy>0</ixy>
            <ixz>0</ixz>
            <iyy>1</iyy>
            <iyz>0</iyz>
            <izz>1</izz>
          </inertia>
          <mass>1</mass>
        </inertial>
        <kinematic>0</kinematic>
        <gravity>1</gravity>
      </link>
      <link name='left_front_wheel'>
        <pose frame=''>0.125 0.201 -0.06 1.5707 -0 0</pose>
        <collision name='collision'>
          <geometry>
            <cylinder>
              <radius>0.11</radius>
              <length>0.075</length>
            </cylinder>
          </geometry>
          <surface>
            <friction>
              <ode>
                <mu>1</mu>
                <mu2>1</mu2>
                <slip1>0.5</slip1>
                <slip2>0</slip2>
              </ode>
              <torsional>
                <ode/>
              </torsional>
            </friction>
            <contact>
              <ode/>
            </contact>
            <bounce/>
          </surface>
          <max_contacts>10</max_contacts>
        </collision>
        <visual name='visual'>
          <geometry>
            <mesh>
              <uri>model://pioneer3at/meshes/wheel.dae</uri>
              <scale>1 1 1</scale>
            </mesh>
          </geometry>
        </visual>
        <self_collide>0</self_collide>
        <inertial>
          <inertia>
            <ixx>1</ixx>
            <ixy>0</ixy>
            <ixz>0</ixz>
            <iyy>1</iyy>
            <iyz>0</iyz>
            <izz>1</izz>
          </inertia>
          <mass>1</mass>
        </inertial>
        <kinematic>0</kinematic>
        <gravity>1</gravity>
      </link>
      <link name='right_rear_wheel'>
        <pose frame=''>-0.125 -0.201 -0.06 1.5707 -0 0</pose>
        <collision name='collision'>
          <geometry>
            <cylinder>
              <radius>0.11</radius>
              <length>0.075</length>
            </cylinder>
          </geometry>
          <surface>
            <friction>
              <ode>
                <mu>1</mu>
                <mu2>1</mu2>
                <slip1>0.5</slip1>
                <slip2>0</slip2>
              </ode>
              <torsional>
                <ode/>
              </torsional>
            </friction>
            <contact>
              <ode/>
            </contact>
            <bounce/>
          </surface>
          <max_contacts>10</max_contacts>
        </collision>
        <visual name='visual'>
          <geometry>
            <mesh>
              <uri>model://pioneer3at/meshes/wheel.dae</uri>
              <scale>1 1 1</scale>
            </mesh>
          </geometry>
        </visual>
        <self_collide>0</self_collide>
        <inertial>
          <inertia>
            <ixx>1</ixx>
            <ixy>0</ixy>
            <ixz>0</ixz>
            <iyy>1</iyy>
            <iyz>0</iyz>
            <izz>1</izz>
          </inertia>
          <mass>1</mass>
        </inertial>
        <kinematic>0</kinematic>
        <gravity>1</gravity>
      </link>
      <link name='left_rear_wheel'>
        <pose frame=''>-0.125 0.201 -0.06 1.5707 -0 0</pose>
        <collision name='collision'>
          <geometry>
            <cylinder>
              <radius>0.11</radius>
              <length>0.075</length>
            </cylinder>
          </geometry>
          <surface>
            <friction>
              <ode>
                <mu>1</mu>
                <mu2>1</mu2>
                <slip1>0.5</slip1>
                <slip2>0</slip2>
              </ode>
              <torsional>
                <ode/>
              </torsional>
            </friction>
            <contact>
              <ode/>
            </contact>
            <bounce/>
          </surface>
          <max_contacts>10</max_contacts>
        </collision>
        <visual name='visual'>
          <geometry>
            <mesh>
              <uri>model://pioneer3at/meshes/wheel.dae</uri>
              <scale>1 1 1</scale>
            </mesh>
          </geometry>
        </visual>
        <self_collide>0</self_collide>
        <inertial>
          <inertia>
            <ixx>1</ixx>
            <ixy>0</ixy>
            <ixz>0</ixz>
            <iyy>1</iyy>
            <iyz>0</iyz>
            <izz>1</izz>
          </inertia>
          <mass>1</mass>
        </inertial>
        <kinematic>0</kinematic>
        <gravity>1</gravity>
      </link>
      <joint name='right_front' type='revolute'>
        <pose frame=''>0 0 0 0 -0 0</pose>
        <child>right_front_wheel</child>
        <parent>chassis</parent>
        <axis>
          <xyz>0 1 0</xyz>
          <use_parent_model_frame>1</use_parent_model_frame>
          <limit>
            <lower>-1e+16</lower>
            <upper>1e+16</upper>
          </limit>
          <dynamics>
            <spring_reference>0</spring_reference>
            <spring_stiffness>0</spring_stiffness>
          </dynamics>
        </axis>
      </joint>
      <joint name='right_rear' type='revolute'>
        <pose frame=''>0 0 0 0 -0 0</pose>
        <child>right_rear_wheel</child>
        <parent>chassis</parent>
        <axis>
          <xyz>0 1 0</xyz>
          <use_parent_model_frame>1</use_parent_model_frame>
          <limit>
            <lower>-1e+16</lower>
            <upper>1e+16</upper>
          </limit>
          <dynamics>
            <spring_reference>0</spring_reference>
            <spring_stiffness>0</spring_stiffness>
          </dynamics>
        </axis>
      </joint>
      <joint name='left_front' type='revolute'>
        <pose frame=''>0 0 0 0 -0 0</pose>
        <child>left_front_wheel</child>
        <parent>chassis</parent>
        <axis>
          <xyz>0 1 0</xyz>
          <use_parent_model_frame>1</use_parent_model_frame>
          <limit>
            <lower>-1e+16</lower>
            <upper>1e+16</upper>
          </limit>
          <dynamics>
            <spring_reference>0</spring_reference>
            <spring_stiffness>0</spring_stiffness>
          </dynamics>
        </axis>
      </joint>
      <joint name='left_rear' type='revolute'>
        <pose frame=''>0 0 0 0 -0 0</pose>
        <child>left_rear_wheel</child>
        <parent>chassis</parent>
        <axis>
          <xyz>0 1 0</xyz>
          <use_parent_model_frame>1</use_parent_model_frame>
          <limit>
            <lower>-1e+16</lower>
            <upper>1e+16</upper>
          </limit>
          <dynamics>
            <spring_reference>0</spring_reference>
            <spring_stiffness>0</spring_stiffness>
          </dynamics>
        </axis>
      </joint>
    </model>
    <model name='pioneer2dx_0'>
      <link name='chassis'>
        <pose frame=''>0 0 0.16 0 -0 0</pose>
        <inertial>
          <mass>5</mass>
          <inertia>
            <ixx>1</ixx>
            <ixy>0</ixy>
            <ixz>0</ixz>
            <iyy>1</iyy>
            <iyz>0</iyz>
            <izz>1</izz>
          </inertia>
        </inertial>
        <collision name='collision'>
          <geometry>
            <box>
              <size>0.445 0.277 0.17</size>
            </box>
          </geometry>
          <max_contacts>10</max_contacts>
          <surface>
            <contact>
              <ode/>
            </contact>
            <bounce/>
            <friction>
              <torsional>
                <ode/>
              </torsional>
              <ode/>
            </friction>
          </surface>
        </collision>
        <collision name='castor_collision'>
          <pose frame=''>-0.2 0 -0.12 0 -0 0</pose>
          <geometry>
            <sphere>
              <radius>0.04</radius>
            </sphere>
          </geometry>
          <surface>
            <friction>
              <ode>
                <mu>0</mu>
                <mu2>0</mu2>
                <slip1>1</slip1>
                <slip2>1</slip2>
              </ode>
              <torsional>
                <ode/>
              </torsional>
            </friction>
            <contact>
              <ode/>
            </contact>
            <bounce/>
          </surface>
          <max_contacts>10</max_contacts>
        </collision>
        <visual name='visual'>
          <pose frame=''>0 0 0.04 0 -0 0</pose>
          <geometry>
            <mesh>
              <uri>model://pioneer2dx/meshes/chassis.dae</uri>
              <scale>1 1 1</scale>
            </mesh>
          </geometry>
        </visual>
        <visual name='castor_visual'>
          <pose frame=''>-0.2 0 -0.12 0 -0 0</pose>
          <geometry>
            <sphere>
              <radius>0.04</radius>
            </sphere>
          </geometry>
          <material>
            <script>
              <uri>file://media/materials/scripts/gazebo.material</uri>
              <name>Gazebo/FlatBlack</name>
            </script>
          </material>
        </visual>
        <self_collide>0</self_collide>
        <kinematic>0</kinematic>
        <gravity>1</gravity>
      </link>
      <link name='right_wheel'>
        <pose frame=''>0.1 -0.17 0.11 -0 1.5707 1.5707</pose>
        <inertial>
          <mass>0.1</mass>
          <inertia>
            <ixx>1</ixx>
            <ixy>0</ixy>
            <ixz>0</ixz>
            <iyy>1</iyy>
            <iyz>0</iyz>
            <izz>1</izz>
          </inertia>
        </inertial>
        <collision name='collision'>
          <geometry>
            <cylinder>
              <radius>0.11</radius>
              <length>0.05</length>
            </cylinder>
          </geometry>
          <surface>
            <friction>
              <ode>
                <mu>100000</mu>
                <mu2>100000</mu2>
                <slip1>0</slip1>
                <slip2>0</slip2>
              </ode>
              <torsional>
                <ode/>
              </torsional>
            </friction>
            <contact>
              <ode/>
            </contact>
            <bounce/>
          </surface>
          <max_contacts>10</max_contacts>
        </collision>
        <visual name='visual'>
          <geometry>
            <cylinder>
              <radius>0.11</radius>
              <length>0.05</length>
            </cylinder>
          </geometry>
          <material>
            <script>
              <uri>file://media/materials/scripts/gazebo.material</uri>
              <name>Gazebo/FlatBlack</name>
            </script>
          </material>
        </visual>
        <self_collide>0</self_collide>
        <kinematic>0</kinematic>
        <gravity>1</gravity>
      </link>
      <link name='left_wheel'>
        <pose frame=''>0.1 0.17 0.11 -0 1.5707 1.5707</pose>
        <inertial>
          <mass>0.5</mass>
          <inertia>
            <ixx>1</ixx>
            <ixy>0</ixy>
            <ixz>0</ixz>
            <iyy>1</iyy>
            <iyz>0</iyz>
            <izz>1</izz>
          </inertia>
        </inertial>
        <collision name='collision'>
          <geometry>
            <cylinder>
              <radius>0.11</radius>
              <length>0.05</length>
            </cylinder>
          </geometry>
          <surface>
            <friction>
              <ode>
                <mu>100000</mu>
                <mu2>100000</mu2>
                <slip1>0</slip1>
                <slip2>0</slip2>
              </ode>
              <torsional>
                <ode/>
              </torsional>
            </friction>
            <contact>
              <ode/>
            </contact>
            <bounce/>
          </surface>
          <max_contacts>10</max_contacts>
        </collision>
        <visual name='visual'>
          <geometry>
            <cylinder>
              <radius>0.11</radius>
              <length>0.05</length>
            </cylinder>
          </geometry>
          <material>
            <script>
              <uri>file://media/materials/scripts/gazebo.material</uri>
              <name>Gazebo/FlatBlack</name>
            </script>
          </material>
        </visual>
        <self_collide>0</self_collide>
        <kinematic>0</kinematic>
        <gravity>1</gravity>
      </link>
      <joint name='left_wheel_hinge' type='revolute'>
        <pose frame=''>0 0 -0.03 0 -0 0</pose>
        <child>left_wheel</child>
        <parent>chassis</parent>
        <axis>
          <xyz>0 1 0</xyz>
          <use_parent_model_frame>1</use_parent_model_frame>
          <limit>
            <lower>-1e+16</lower>
            <upper>1e+16</upper>
          </limit>
          <dynamics>
            <spring_reference>0</spring_reference>
            <spring_stiffness>0</spring_stiffness>
          </dynamics>
        </axis>
      </joint>
      <joint name='right_wheel_hinge' type='revolute'>
        <pose frame=''>0 0 0.03 0 -0 0</pose>
        <child>right_wheel</child>
        <parent>chassis</parent>
        <axis>
          <xyz>0 1 0</xyz>
          <use_parent_model_frame>1</use_parent_model_frame>
          <limit>
            <lower>-1e+16</lower>
            <upper>1e+16</upper>
          </limit>
          <dynamics>
            <spring_reference>0</spring_reference>
            <spring_stiffness>0</spring_stiffness>
          </dynamics>
        </axis>
      </joint>
      <plugin name='diff_drive' filename='libDiffDrivePlugin.so'>
        <left_joint>left_wheel_hinge</left_joint>
        <right_joint>right_wheel_hinge</right_joint>
        <torque>5</torque>
      </plugin>
      <pose frame=''>1.54953 4.3304 0 0 -0 0</pose>
    </model>
    <model name='pioneer3at_0'>
      <pose frame=''>9.00907 6.35306 0.18 0 -0 0</pose>
      <static>0</static>
      <link name='chassis'>
        <inertial>
          <mass>14</mass>
          <inertia>
            <ixx>0.3338</ixx>
            <ixy>0</ixy>
            <ixz>0</ixz>
            <iyy>0.4783</iyy>
            <iyz>0</iyz>
            <izz>0.3338</izz>
          </inertia>
        </inertial>
        <collision name='collision'>
          <geometry>
            <box>
              <size>0.501 0.4 0.19</size>
            </box>
          </geometry>
          <max_contacts>10</max_contacts>
          <surface>
            <contact>
              <ode/>
            </contact>
            <bounce/>
            <friction>
              <torsional>
                <ode/>
              </torsional>
              <ode/>
            </friction>
          </surface>
        </collision>
        <visual name='visual'>
          <geometry>
            <mesh>
              <uri>model://pioneer3at/meshes/chassis.dae</uri>
              <scale>1 1 1</scale>
            </mesh>
          </geometry>
        </visual>
        <self_collide>0</self_collide>
        <kinematic>0</kinematic>
        <gravity>1</gravity>
      </link>
      <link name='right_front_wheel'>
        <pose frame=''>0.125 -0.201 -0.06 1.5707 -0 0</pose>
        <collision name='collision'>
          <geometry>
            <cylinder>
              <radius>0.11</radius>
              <length>0.075</length>
            </cylinder>
          </geometry>
          <surface>
            <friction>
              <ode>
                <mu>1</mu>
                <mu2>1</mu2>
                <slip1>0.5</slip1>
                <slip2>0</slip2>
              </ode>
              <torsional>
                <ode/>
              </torsional>
            </friction>
            <contact>
              <ode/>
            </contact>
            <bounce/>
          </surface>
          <max_contacts>10</max_contacts>
        </collision>
        <visual name='visual'>
          <geometry>
            <mesh>
              <uri>model://pioneer3at/meshes/wheel.dae</uri>
              <scale>1 1 1</scale>
            </mesh>
          </geometry>
        </visual>
        <self_collide>0</self_collide>
        <inertial>
          <inertia>
            <ixx>1</ixx>
            <ixy>0</ixy>
            <ixz>0</ixz>
            <iyy>1</iyy>
            <iyz>0</iyz>
            <izz>1</izz>
          </inertia>
          <mass>1</mass>
        </inertial>
        <kinematic>0</kinematic>
        <gravity>1</gravity>
      </link>
      <link name='left_front_wheel'>
        <pose frame=''>0.125 0.201 -0.06 1.5707 -0 0</pose>
        <collision name='collision'>
          <geometry>
            <cylinder>
              <radius>0.11</radius>
              <length>0.075</length>
            </cylinder>
          </geometry>
          <surface>
            <friction>
              <ode>
                <mu>1</mu>
                <mu2>1</mu2>
                <slip1>0.5</slip1>
                <slip2>0</slip2>
              </ode>
              <torsional>
                <ode/>
              </torsional>
            </friction>
            <contact>
              <ode/>
            </contact>
            <bounce/>
          </surface>
          <max_contacts>10</max_contacts>
        </collision>
        <visual name='visual'>
          <geometry>
            <mesh>
              <uri>model://pioneer3at/meshes/wheel.dae</uri>
              <scale>1 1 1</scale>
            </mesh>
          </geometry>
        </visual>
        <self_collide>0</self_collide>
        <inertial>
          <inertia>
            <ixx>1</ixx>
            <ixy>0</ixy>
            <ixz>0</ixz>
            <iyy>1</iyy>
            <iyz>0</iyz>
            <izz>1</izz>
          </inertia>
          <mass>1</mass>
        </inertial>
        <kinematic>0</kinematic>
        <gravity>1</gravity>
      </link>
      <link name='right_rear_wheel'>
        <pose frame=''>-0.125 -0.201 -0.06 1.5707 -0 0</pose>
        <collision name='collision'>
          <geometry>
            <cylinder>
              <radius>0.11</radius>
              <length>0.075</length>
            </cylinder>
          </geometry>
          <surface>
            <friction>
              <ode>
                <mu>1</mu>
                <mu2>1</mu2>
                <slip1>0.5</slip1>
                <slip2>0</slip2>
              </ode>
              <torsional>
                <ode/>
              </torsional>
            </friction>
            <contact>
              <ode/>
            </contact>
            <bounce/>
          </surface>
          <max_contacts>10</max_contacts>
        </collision>
        <visual name='visual'>
          <geometry>
            <mesh>
              <uri>model://pioneer3at/meshes/wheel.dae</uri>
              <scale>1 1 1</scale>
            </mesh>
          </geometry>
        </visual>
        <self_collide>0</self_collide>
        <inertial>
          <inertia>
            <ixx>1</ixx>
            <ixy>0</ixy>
            <ixz>0</ixz>
            <iyy>1</iyy>
            <iyz>0</iyz>
            <izz>1</izz>
          </inertia>
          <mass>1</mass>
        </inertial>
        <kinematic>0</kinematic>
        <gravity>1</gravity>
      </link>
      <link name='left_rear_wheel'>
        <pose frame=''>-0.125 0.201 -0.06 1.5707 -0 0</pose>
        <collision name='collision'>
          <geometry>
            <cylinder>
              <radius>0.11</radius>
              <length>0.075</length>
            </cylinder>
          </geometry>
          <surface>
            <friction>
              <ode>
                <mu>1</mu>
                <mu2>1</mu2>
                <slip1>0.5</slip1>
                <slip2>0</slip2>
              </ode>
              <torsional>
                <ode/>
              </torsional>
            </friction>
            <contact>
              <ode/>
            </contact>
            <bounce/>
          </surface>
          <max_contacts>10</max_contacts>
        </collision>
        <visual name='visual'>
          <geometry>
            <mesh>
              <uri>model://pioneer3at/meshes/wheel.dae</uri>
              <scale>1 1 1</scale>
            </mesh>
          </geometry>
        </visual>
        <self_collide>0</self_collide>
        <inertial>
          <inertia>
            <ixx>1</ixx>
            <ixy>0</ixy>
            <ixz>0</ixz>
            <iyy>1</iyy>
            <iyz>0</iyz>
            <izz>1</izz>
          </inertia>
          <mass>1</mass>
        </inertial>
        <kinematic>0</kinematic>
        <gravity>1</gravity>
      </link>
      <joint name='right_front' type='revolute'>
        <pose frame=''>0 0 0 0 -0 0</pose>
        <child>right_front_wheel</child>
        <parent>chassis</parent>
        <axis>
          <xyz>0 1 0</xyz>
          <use_parent_model_frame>1</use_parent_model_frame>
          <limit>
            <lower>-1e+16</lower>
            <upper>1e+16</upper>
          </limit>
          <dynamics>
            <spring_reference>0</spring_reference>
            <spring_stiffness>0</spring_stiffness>
          </dynamics>
        </axis>
      </joint>
      <joint name='right_rear' type='revolute'>
        <pose frame=''>0 0 0 0 -0 0</pose>
        <child>right_rear_wheel</child>
        <parent>chassis</parent>
        <axis>
          <xyz>0 1 0</xyz>
          <use_parent_model_frame>1</use_parent_model_frame>
          <limit>
            <lower>-1e+16</lower>
            <upper>1e+16</upper>
          </limit>
          <dynamics>
            <spring_reference>0</spring_reference>
            <spring_stiffness>0</spring_stiffness>
          </dynamics>
        </axis>
      </joint>
      <joint name='left_front' type='revolute'>
        <pose frame=''>0 0 0 0 -0 0</pose>
        <child>left_front_wheel</child>
        <parent>chassis</parent>
        <axis>
          <xyz>0 1 0</xyz>
          <use_parent_model_frame>1</use_parent_model_frame>
          <limit>
            <lower>-1e+16</lower>
            <upper>1e+16</upper>
          </limit>
          <dynamics>
            <spring_reference>0</spring_reference>
            <spring_stiffness>0</spring_stiffness>
          </dynamics>
        </axis>
      </joint>
      <joint name='left_rear' type='revolute'>
        <pose frame=''>0 0 0 0 -0 0</pose>
        <child>left_rear_wheel</child>
        <parent>chassis</parent>
        <axis>
          <xyz>0 1 0</xyz>
          <use_parent_model_frame>1</use_parent_model_frame>
          <limit>
            <lower>-1e+16</lower>
            <upper>1e+16</upper>
          </limit>
          <dynamics>
            <spring_reference>0</spring_reference>
            <spring_stiffness>0</spring_stiffness>
          </dynamics>
        </axis>
      </joint>
    </model>
    <state world_name='default'>
      <sim_time>157 413000000</sim_time>
      <real_time>160 636741304</real_time>
      <wall_time>1562292696 131379490</wall_time>
      <iterations>157413</iterations>
      <model name='Untitled'>
        <pose frame=''>1.50483 -0.146788 0 0 -0 0</pose>
        <scale>1 1 1</scale>
        <link name='Wall_0'>
          <pose frame=''>11.8048 -1.89679 0 0 -0 1.5708</pose>
          <velocity>0 0 0 0 -0 0</velocity>
          <acceleration>0 0 0 0 -0 0</acceleration>
          <wrench>0 0 0 0 -0 0</wrench>
        </link>
        <link name='Wall_1'>
          <pose frame=''>11.8048 6.82821 0 0 -0 1.5708</pose>
          <velocity>0 0 0 0 -0 0</velocity>
          <acceleration>0 0 0 0 -0 0</acceleration>
          <wrench>0 0 0 0 -0 0</wrench>
        </link>
        <link name='Wall_3'>
          <pose frame=''>1.50483 -9.07179 0 0 -0 3.14159</pose>
          <velocity>0 0 0 0 -0 0</velocity>
          <acceleration>0 0 0 0 -0 0</acceleration>
          <wrench>0 0 0 0 -0 0</wrench>
        </link>
        <link name='Wall_4'>
          <pose frame=''>-8.79517 -0.146788 0 0 -0 1.5708</pose>
          <velocity>0 0 0 0 -0 0</velocity>
          <acceleration>0 0 0 0 -0 0</acceleration>
          <wrench>0 0 0 0 -0 0</wrench>
        </link>
        <link name='Wall_5'>
          <pose frame=''>1.50483 8.77821 0 0 -0 0</pose>
          <velocity>0 0 0 0 -0 0</velocity>
          <acceleration>0 0 0 0 -0 0</acceleration>
          <wrench>0 0 0 0 -0 0</wrench>
        </link>
        <link name='Wall_6'>
          <pose frame=''>11.8048 8.22821 0 0 0 -1.5708</pose>
          <velocity>0 0 0 0 -0 0</velocity>
          <acceleration>0 0 0 0 -0 0</acceleration>
          <wrench>0 0 0 0 -0 0</wrench>
        </link>
      </model>
      <model name='cafe_table'>
        <pose frame=''>9.22152 -5.31249 0 0 -0 0</pose>
        <scale>1 1 1</scale>
        <link name='link'>
          <pose frame=''>9.22152 -5.31249 0 0 -0 0</pose>
          <velocity>0 0 0 0 -0 0</velocity>
          <acceleration>0 0 0 0 -0 0</acceleration>
          <wrench>0 0 0 0 -0 0</wrench>
        </link>
      </model>
      <model name='cube_20k'>
        <pose frame=''>-3.73378 -7.06091 0 0 0 -1.6e-05</pose>
        <scale>1 1 1</scale>
        <link name='link'>
          <pose frame=''>-3.73378 -7.06091 0.5 0 0 -1.6e-05</pose>
          <velocity>0 0 0 0 -0 0</velocity>
          <acceleration>-1.07556 -0.034256 0.19878 -3.07097 -0.991637 -3.13739</acceleration>
          <wrench>-1.07556 -0.034256 0.19878 0 -0 0</wrench>
        </link>
      </model>
      <model name='cube_20k_0'>
        <pose frame=''>-0.283553 -6.91074 0 0 1e-06 -1.4e-05</pose>
        <scale>1 1 1</scale>
        <link name='link'>
          <pose frame=''>-0.283552 -6.91074 0.5 0 1e-06 -1.4e-05</pose>
          <velocity>0 0 0 0 -0 0</velocity>
          <acceleration>1.07556 0.034258 -0.19878 3.07097 0.991637 3.13739</acceleration>
          <wrench>1.07556 0.034258 -0.19878 0 -0 0</wrench>
        </link>
      </model>
      <model name='cube_20k_1'>
        <pose frame=''>3.34153 -6.96407 0 0 0 -1.2e-05</pose>
        <scale>1 1 1</scale>
        <link name='link'>
          <pose frame=''>3.34153 -6.96407 0.5 0 0 -1.2e-05</pose>
          <velocity>0 0 0 0 -0 0</velocity>
          <acceleration>-1.07556 -0.03426 0.19878 -3.07097 -0.991637 -3.13739</acceleration>
          <wrench>-1.07556 -0.03426 0.19878 0 -0 0</wrench>
        </link>
      </model>
      <model name='cube_20k_2'>
        <pose frame=''>6.77413 -6.96441 0 0 1e-06 -1.1e-05</pose>
        <scale>1 1 1</scale>
        <link name='link'>
          <pose frame=''>6.77413 -6.96441 0.5 0 1e-06 -1.1e-05</pose>
          <velocity>0 0 0 0 -0 0</velocity>
          <acceleration>1.07556 0.034262 -0.19878 3.07096 0.991637 3.13739</acceleration>
          <wrench>1.07556 0.034262 -0.19878 0 -0 0</wrench>
        </link>
      </model>
      <model name='ground_plane'>
        <pose frame=''>0 0 0 0 -0 0</pose>
        <scale>1 1 1</scale>
        <link name='link'>
          <pose frame=''>0 0 0 0 -0 0</pose>
          <velocity>0 0 0 0 -0 0</velocity>
          <acceleration>0 0 0 0 -0 0</acceleration>
          <wrench>0 0 0 0 -0 0</wrench>
        </link>
      </model>
      <model name='pioneer2dx'>
        <pose frame=''>-5.00691 -4.62117 -1e-06 2e-05 3e-06 -0.015748</pose>
        <scale>1 1 1</scale>
        <link name='chassis'>
          <pose frame=''>-5.00691 -4.62118 0.159999 2e-05 3e-06 -0.015748</pose>
          <velocity>5.7e-05 -8.4e-05 0.000237 0.001004 -0.001148 -0.000362</velocity>
          <acceleration>-0.011212 -0.090459 0.474101 -1.13329 -0.846246 3.12742</acceleration>
          <wrench>-0.056059 -0.452293 2.37051 0 -0 0</wrench>
        </link>
        <link name='left_wheel'>
          <pose frame=''>-4.90425 -4.45277 0.110003 0.031243 1.57068 1.5862</pose>
          <velocity>0.000133 -0.000111 0.00063 0.00102 0.001116 -0.000362</velocity>
          <acceleration>0.063933 -0.031807 1.1537 2.02392 -0.031883 -0.014506</acceleration>
          <wrench>0.031967 -0.015904 0.57685 0 -0 0</wrench>
        </link>
        <link name='right_wheel'>
          <pose frame=''>-4.9096 -4.79273 0.110002 0.064394 1.57068 1.61935</pose>
          <velocity>0.000115 -0.000257 -0.001428 0.001045 0.001115 -0.000361</velocity>
          <acceleration>0.164363 -0.178959 -1.2515 2.04933 -0.032278 -0.014</acceleration>
          <wrench>0.016436 -0.017896 -0.12515 0 -0 0</wrench>
        </link>
      </model>
      <model name='pioneer2dx_0'>
        <pose frame=''>1.55184 4.32899 -1e-06 1.9e-05 4e-06 -0.013071</pose>
        <scale>1 1 1</scale>
        <link name='chassis'>
          <pose frame=''>1.55184 4.32899 0.159999 1.9e-05 4e-06 -0.013071</pose>
          <velocity>6.8e-05 7e-06 -0.000237 -0.001007 0.001145 -0.000347</velocity>
          <acceleration>0.010969 0.090488 -0.474101 1.12715 0.851631 -3.12742</acceleration>
          <wrench>0.054847 0.452442 -2.37051 0 -0 0</wrench>
        </link>
        <link name='left_wheel'>
          <pose frame=''>1.65405 4.49766 0.110002 0.021567 1.57068 1.57919</pose>
          <velocity>0.000111 -3.9e-05 -0.00063 -0.001017 -0.001119 -0.000347</velocity>
          <acceleration>-0.064018 0.031636 -1.1537 -2.024 0.026469 0.014506</acceleration>
          <wrench>-0.032009 0.015818 -0.57685 0 -0 0</wrench>
        </link>
        <link name='right_wheel'>
          <pose frame=''>1.64961 4.15769 0.110004 0.050367 1.57068 1.608</pose>
          <velocity>-0.000113 0.00011 0.001428 -0.001042 -0.001118 -0.000348</velocity>
          <acceleration>-0.164841 0.178518 1.2515 -2.0494 0.026939 0.014</acceleration>
          <wrench>-0.016484 0.017852 0.12515 0 -0 0</wrench>
        </link>
      </model>
      <model name='pioneer3at'>
        <pose frame=''>-2.4086 -4.37197 0.17 7e-06 1.8e-05 -0.001717</pose>
        <scale>1 1 1</scale>
        <link name='chassis'>
          <pose frame=''>-2.4086 -4.37197 0.17 7e-06 1.8e-05 -0.001717</pose>
          <velocity>0.00042 -0.000804 -0.003927 0.006398 0.019228 -0.000173</velocity>
          <acceleration>0.601753 -0.579624 -4.40563 1.67053 0.514871 3.12429</acceleration>
          <wrench>8.42454 -8.11473 -61.6788 0 -0 0</wrench>
        </link>
        <link name='left_front_wheel'>
          <pose frame=''>-2.28326 -4.17119 0.109999 1.57071 0.06301 -0.001717</pose>
          <velocity>-0.00076 -0.000462 -0.00501 0.006362 0.001125 -0.000178</velocity>
          <acceleration>-0.876921 -0.28787 -6.18007 -1.50524 -0.008204 -0.039637</acceleration>
          <wrench>-0.876921 -0.28787 -6.18007 0 -0 0</wrench>
        </link>
        <link name='left_rear_wheel'>
          <pose frame=''>-2.53326 -4.17076 0.110003 1.57071 -0.070191 -0.001718</pose>
          <velocity>-0.000377 -0.000689 -0.000206 0.006306 -0.003321 -0.000216</velocity>
          <acceleration>-0.087895 -0.527176 -0.614778 -1.45634 -0.684096 -0.132776</acceleration>
          <wrench>-0.087895 -0.527176 -0.614778 0 -0 0</wrench>
        </link>
        <link name='right_front_wheel'>
          <pose frame=''>-2.28395 -4.57319 0.109996 1.57071 0.057816 -0.001717</pose>
          <velocity>-0.000811 -0.000516 -0.007664 0.006366 0.002186 -0.000173</velocity>
          <acceleration>-0.681155 -0.275534 -8.04632 -1.48481 -0.008239 -0.02166</acceleration>
          <wrench>-0.681155 -0.275534 -8.04632 0 -0 0</wrench>
        </link>
        <link name='right_rear_wheel'>
          <pose frame=''>-2.53395 -4.57276 0.110001 1.57071 -0.048754 -0.001718</pose>
          <velocity>-0.000695 -0.000423 -0.002805 0.006352 -0.000369 -0.000166</velocity>
          <acceleration>-0.65152 -0.254928 -2.76824 -1.46019 -0.008281 -0.037212</acceleration>
          <wrench>-0.65152 -0.254928 -2.76824 0 -0 0</wrench>
        </link>
      </model>
      <model name='pioneer3at_0'>
        <pose frame=''>9.00839 6.35286 0.170004 4e-06 -8e-06 -0.001439</pose>
        <scale>1 1 1</scale>
        <link name='chassis'>
          <pose frame=''>9.00839 6.35286 0.170004 4e-06 -8e-06 -0.001439</pose>
          <velocity>-0.000557 -0.00087 -0.000183 0.005589 -0.009338 0.0003</velocity>
          <acceleration>0.262976 -0.497949 -3.57841 2.18886 1.47339 0.322659</acceleration>
          <wrench>3.68166 -6.97128 -50.0978 0 -0 0</wrench>
        </link>
        <link name='left_front_wheel'>
          <pose frame=''>9.13368 6.55368 0.110006 1.5707 0.052914 -0.001439</pose>
          <velocity>-9.3e-05 -0.00042 0.002028 0.005623 0.000914 0.000302</velocity>
          <acceleration>-0.195156 -0.045645 -4.68376 2.18851 -0.00315 0.278309</acceleration>
          <wrench>-0.195156 -0.045645 -4.68376 0 -0 0</wrench>
        </link>
        <link name='left_rear_wheel'>
          <pose frame=''>8.88368 6.55404 0.110003 1.5707 -0.058962 -0.001439</pose>
          <velocity>-2.2e-05 -0.00062 -0.00017 0.005653 -0.000308 0.000288</velocity>
          <acceleration>0.018264 -0.276927 -1.97865 2.50525 0.113837 0.243129</acceleration>
          <wrench>0.018264 -0.276927 -1.97865 0 -0 0</wrench>
        </link>
        <link name='right_front_wheel'>
          <pose frame=''>9.1331 6.15168 0.110003 1.5707 0.0486 -0.001439</pose>
          <velocity>0.000232 -0.000614 -9.3e-05 0.00559 0.002032 0.000298</velocity>
          <acceleration>-0.043319 -0.237429 -4.50729 2.15306 -0.485434 0.315825</acceleration>
          <wrench>-0.043319 -0.237429 -4.50729 0 -0 0</wrench>
        </link>
        <link name='right_rear_wheel'>
          <pose frame=''>8.8831 6.15204 0.110002 1.5707 -0.04103 -0.00144</pose>
          <velocity>5.1e-05 -0.000646 -0.002491 0.005623 -0.001818 0.000299</velocity>
          <acceleration>-0.155829 -0.380228 -3.06849 2.31186 -0.003328 0.283667</acceleration>
          <wrench>-0.155829 -0.380228 -3.06849 0 -0 0</wrench>
        </link>
      </model>
      <model name='unit_box_0'>
        <pose frame=''>-6.96471 -6.96388 0.499995 0 1e-05 0</pose>
        <scale>1 1 1</scale>
        <link name='link'>
          <pose frame=''>-6.96471 -6.96388 0.499995 0 1e-05 0</pose>
          <velocity>0 0 0 0 -0 0</velocity>
          <acceleration>0.010615 -0.006191 -9.78231 0.012424 0.021225 1.8e-05</acceleration>
          <wrench>0.010615 -0.006191 -9.78231 0 -0 0</wrench>
        </link>
      </model>
      <model name='unit_box_1'>
        <pose frame=''>-7.07039 7.24524 0.499995 -1e-05 0 0</pose>
        <scale>1 1 1</scale>
        <link name='link'>
          <pose frame=''>-7.07039 7.24524 0.499995 -1e-05 0 0</pose>
          <velocity>0 0 0 0 -0 0</velocity>
          <acceleration>0.004709 0.011055 -9.78158 -0.022108 0.009414 1e-06</acceleration>
          <wrench>0.004709 0.011055 -9.78158 0 -0 0</wrench>
        </link>
      </model>
      <model name='unit_cylinder_0'>
        <pose frame=''>-2.96281 7.34822 0.499992 -3e-06 3e-06 0</pose>
        <scale>1 1 1</scale>
        <link name='link'>
          <pose frame=''>-2.96281 7.34822 0.499992 -3e-06 3e-06 0</pose>
          <velocity>0 0 0 0 -0 0</velocity>
          <acceleration>0 0 -9.8 0 -0 0</acceleration>
          <wrench>0 0 -9.8 0 -0 0</wrench>
        </link>
      </model>
      <model name='unit_cylinder_1'>
        <pose frame=''>0.419895 7.25053 0.499998 3e-06 -3e-06 0</pose>
        <scale>1 1 1</scale>
        <link name='link'>
          <pose frame=''>0.419895 7.25053 0.499998 3e-06 -3e-06 0</pose>
          <velocity>0 0 0 0 -0 0</velocity>
          <acceleration>0 0 -9.8 0 -0 0</acceleration>
          <wrench>0 0 -9.8 0 -0 0</wrench>
        </link>
      </model>
      <model name='unit_cylinder_2'>
        <pose frame=''>3.58677 7.36506 0.499992 -3e-06 3e-06 0</pose>
        <scale>1 1 1</scale>
        <link name='link'>
          <pose frame=''>3.58677 7.36506 0.499992 -3e-06 3e-06 0</pose>
          <velocity>0 0 0 0 -0 0</velocity>
          <acceleration>0 0 -9.8 0 -0 0</acceleration>
          <wrench>0 0 -9.8 0 -0 0</wrench>
        </link>
      </model>
      <model name='unit_sphere_0'>
        <pose frame=''>6.37672 7.04879 0.5 0 -0 0</pose>
        <scale>1 1 1</scale>
        <link name='link'>
          <pose frame=''>6.37672 7.04879 0.5 0 -0 0</pose>
          <velocity>0 0 0 0 -0 0</velocity>
          <acceleration>0 0 0 0 -0 0</acceleration>
          <wrench>0 0 0 0 -0 0</wrench>
        </link>
      </model>
      <light name='sun'>
        <pose frame=''>0 0 10 0 -0 0</pose>
      </light>
    </state>
    <gui fullscreen='0'>
      <camera name='user_camera'>
        <pose frame=''>16.7232 -14.7065 26.9501 0 0.903644 2.2642</pose>
        <view_controller>orbit</view_controller>
        <projection_type>perspective</projection_type>
      </camera>
    </gui>
  </world>
</sdf>
